<?xml version='1.0' encoding='utf-8'?>
<robot xmlns:ns0="http://www.ros.org/wiki/xacro" name="cobotta_mycobot_dual_robot">
  <link name="world" />
  <gazebo>
    <plugin filename="libgazebo_ros_control.so" name="gazebo_ros_control">
      <robotNamespace>/cobotta</robotNamespace>
      <robotSimType>gazebo_ros_control/DefaultRobotHWSim</robotSimType>
      <legacyModeNS>true</legacyModeNS>
    </plugin>
  </gazebo>
  <joint name="cobotta_joint_w" type="fixed">
    <parent link="world" />
    <child link="cobotta_base_link" />
    <origin xyz="0 0 0.022" rpy="0 0 0" />
  </joint>
  <link name="cobotta_base_link">
    <visual>
      <origin rpy="0 0 0" xyz="0 0 0" />
      <geometry>
        <mesh filename="package://denso_cobotta_descriptions/cobotta_description/base_link.dae" scale="1 1 1" />
      </geometry>
    </visual>
    <collision>
      <origin rpy="0 0 0" xyz="0 0 0" />
      <geometry>
        <mesh filename="package://denso_cobotta_descriptions/cobotta_description/base_link.dae" scale="1 1 1" />
      </geometry>
    </collision>
    <inertial>
      <mass value="1.4" />
      <origin rpy="0.000000 0.000000 0.000000" xyz="-0.021310 0.000002 0.044011" />
      <inertia ixx="0.0026599999999999996" ixy="0.0" ixz="0.0" iyy="0.0026599999999999996" iyz="0.0" izz="0.00448" />
    </inertial>
  </link>
  <link name="cobotta_J1">
    <visual>
      <origin rpy="0 0 0" xyz="0 0 0" />
      <geometry>
        <mesh filename="package://denso_cobotta_descriptions/cobotta_description/J1.dae" scale="1 1 1" />
      </geometry>
    </visual>
    <collision>
      <origin rpy="0 0 0" xyz="0 0 0" />
      <geometry>
        <mesh filename="package://denso_cobotta_descriptions/cobotta_description/J1.dae" scale="1 1 1" />
      </geometry>
    </collision>
    <inertial>
      <mass value="1.29" />
      <origin rpy="0.000000 0.000000 0.000000" xyz="0.000000 0.000000 0.15" />
      <inertia ixx="0.002236" ixy="0.0" ixz="0.0" iyy="0.002236" iyz="0.0" izz="0.002322" />
    </inertial>
  </link>
  <joint name="cobotta_joint_1" type="revolute">
    <parent link="cobotta_base_link" />
    <child link="cobotta_J1" />
    <origin rpy="0.000000 0.000000 0.000000" xyz="0.000000 0.000000 0.000000" />
    <axis xyz="-0.000000 -0.000000 1.000000" />
    <limit effort="10" lower="-2.617994" upper="2.617994" velocity="0.40317105721069" />
    <dynamics damping="0.001" friction="0.61" />
  </joint>
  <transmission name="cobotta_trans_1">
    <type>transmission_interface/SimpleTransmission</type>
    <joint name="cobotta_joint_1">
      <hardwareInterface>hardware_interface/PositionJointInterface</hardwareInterface>
    </joint>
    <actuator name="cobotta_motor_1">
      <hardwareInterface>hardware_interface/PositionJointInterface</hardwareInterface>
      <mechanicalReduction>1</mechanicalReduction>
    </actuator>
  </transmission>
  <link name="cobotta_J2">
    <visual>
      <origin rpy="0 0 0" xyz="0 0 0" />
      <geometry>
        <mesh filename="package://denso_cobotta_descriptions/cobotta_description/J2.dae" scale="1 1 1" />
      </geometry>
    </visual>
    <collision>
      <origin rpy="0 0 0" xyz="0 0 0" />
      <geometry>
        <mesh filename="package://denso_cobotta_descriptions/cobotta_description/J2.dae" scale="1 1 1" />
      </geometry>
    </collision>
    <inertial>
      <mass value="0.39" />
      <origin rpy="0.000000 0.000000 0.000000" xyz="-0.020000 0.100000 0.070000" />
      <inertia ixx="0.0005557499999999999" ixy="0.0" ixz="0.0" iyy="0.0005557499999999999" iyz="0.0" izz="0.0001755" />
    </inertial>
  </link>
  <joint name="cobotta_joint_2" type="revolute">
    <parent link="cobotta_J1" />
    <child link="cobotta_J2" />
    <origin rpy="0.000000 0.000000 0.000000" xyz="0.000000 0.000000 0.180000" />
    <axis xyz="-0.000000 1.000000 -0.000000" />
    <limit effort="10" lower="-1.047198" upper="1.745329" velocity="0.392175482923126" />
    <dynamics damping="0.001" friction="0.61" />
  </joint>
  <transmission name="cobotta_trans_2">
    <type>transmission_interface/SimpleTransmission</type>
    <joint name="cobotta_joint_2">
      <hardwareInterface>hardware_interface/PositionJointInterface</hardwareInterface>
    </joint>
    <actuator name="cobotta_motor_2">
      <hardwareInterface>hardware_interface/PositionJointInterface</hardwareInterface>
      <mechanicalReduction>1</mechanicalReduction>
    </actuator>
  </transmission>
  <link name="cobotta_J3">
    <visual>
      <origin rpy="0 0 0" xyz="0 0 0" />
      <geometry>
        <mesh filename="package://denso_cobotta_descriptions/cobotta_description/J3.dae" scale="1 1 1" />
      </geometry>
    </visual>
    <collision>
      <origin rpy="0 0 0" xyz="0 0 0" />
      <geometry>
        <mesh filename="package://denso_cobotta_descriptions/cobotta_description/J3.dae" scale="1 1 1" />
      </geometry>
    </collision>
    <inertial>
      <mass value="0.35" />
      <origin rpy="0.000000 0.000000 0.000000" xyz="-0.01000 0.020000 0.030000" />
      <inertia ixx="0.0004316666666666666" ixy="0.0" ixz="0.0" iyy="0.0004316666666666666" iyz="0.0" izz="0.00015749999999999998" />
    </inertial>
  </link>
  <joint name="cobotta_joint_3" type="revolute">
    <parent link="cobotta_J2" />
    <child link="cobotta_J3" />
    <origin rpy="0.000000 0.000000 0.000000" xyz="0.000000 0.000000 0.165000" />
    <axis xyz="-0.000000 1.000000 -0.000000" />
    <limit effort="10" lower="0.3141593" upper="2.443461" velocity="0.725707902979242" />
    <dynamics damping="0.001" friction="0.61" />
  </joint>
  <transmission name="cobotta_trans_3">
    <type>transmission_interface/SimpleTransmission</type>
    <joint name="cobotta_joint_3">
      <hardwareInterface>hardware_interface/PositionJointInterface</hardwareInterface>
    </joint>
    <actuator name="cobotta_motor_3">
      <hardwareInterface>hardware_interface/PositionJointInterface</hardwareInterface>
      <mechanicalReduction>1</mechanicalReduction>
    </actuator>
  </transmission>
  <link name="cobotta_J4">
    <visual>
      <origin rpy="0 0 0" xyz="0 0 0" />
      <geometry>
        <mesh filename="package://denso_cobotta_descriptions/cobotta_description/J4.dae" scale="1 1 1" />
      </geometry>
    </visual>
    <collision>
      <origin rpy="0 0 0" xyz="0 0 0" />
      <geometry>
        <mesh filename="package://denso_cobotta_descriptions/cobotta_description/J4.dae" scale="1 1 1" />
      </geometry>
    </collision>
    <inertial>
      <mass value="0.35" />
      <origin rpy="0.000000 0.000000 0.000000" xyz="0.0000 0.000000 0.055000" />
      <inertia ixx="0.0004316666666666666" ixy="0.0" ixz="0.0" iyy="0.0004316666666666666" iyz="0.0" izz="0.00015749999999999998" />
    </inertial>
  </link>
  <joint name="cobotta_joint_4" type="revolute">
    <parent link="cobotta_J3" />
    <child link="cobotta_J4" />
    <origin rpy="0.000000 0.000000 0.000000" xyz="-0.012000 0.020000 0.088000" />
    <axis xyz="-0.000000 -0.000000 1.000000" />
    <limit effort="10" lower="-2.96706" upper="2.96706" velocity="0.739146938219599" />
    <dynamics damping="0.001" friction="0.61" />
  </joint>
  <transmission name="cobotta_trans_4">
    <type>transmission_interface/SimpleTransmission</type>
    <joint name="cobotta_joint_4">
      <hardwareInterface>hardware_interface/PositionJointInterface</hardwareInterface>
    </joint>
    <actuator name="cobotta_motor_4">
      <hardwareInterface>hardware_interface/PositionJointInterface</hardwareInterface>
      <mechanicalReduction>1</mechanicalReduction>
    </actuator>
  </transmission>
  <link name="cobotta_J5">
    <visual>
      <origin rpy="0 0 0" xyz="0 0 0" />
      <geometry>
        <mesh filename="package://denso_cobotta_descriptions/cobotta_description/J5.dae" scale="1 1 1" />
      </geometry>
    </visual>
    <collision>
      <origin rpy="0 0 0" xyz="0 0 0" />
      <geometry>
        <mesh filename="package://denso_cobotta_descriptions/cobotta_description/J5.dae" scale="1 1 1" />
      </geometry>
    </collision>
    <inertial>
      <mass value="0.19" />
      <origin rpy="0.000000 0.000000 0.000000" xyz="0.000000 -0.040000 0.015000" />
      <inertia ixx="9.974999999999999e-05" ixy="0.0" ixz="0.0" iyy="9.974999999999999e-05" iyz="0.0" izz="8.55e-05" />
    </inertial>
  </link>
  <joint name="cobotta_joint_5" type="revolute">
    <parent link="cobotta_J4" />
    <child link="cobotta_J5" />
    <origin rpy="0.000000 0.000000 0.000000" xyz="0.000000 -0.020000 0.089500" />
    <axis xyz="-0.000000 1.000000 -0.000000" />
    <limit effort="10" lower="-1.658063" upper="2.356194" velocity="0.739146938219599" />
    <dynamics damping="0.001" friction="0.61" />
  </joint>
  <transmission name="cobotta_trans_5">
    <type>transmission_interface/SimpleTransmission</type>
    <joint name="cobotta_joint_5">
      <hardwareInterface>hardware_interface/PositionJointInterface</hardwareInterface>
    </joint>
    <actuator name="cobotta_motor_5">
      <hardwareInterface>hardware_interface/PositionJointInterface</hardwareInterface>
      <mechanicalReduction>1</mechanicalReduction>
    </actuator>
  </transmission>
  <link name="cobotta_J6">
    <visual>
      <origin rpy="0 0 0" xyz="0 0 0" />
      <geometry>
        <mesh filename="package://denso_cobotta_descriptions/cobotta_description/J6.dae" scale="1 1 1" />
      </geometry>
    </visual>
    <collision>
      <origin rpy="0 0 0" xyz="0 0 0" />
      <geometry>
        <mesh filename="package://denso_cobotta_descriptions/cobotta_description/J6.dae" scale="1 1 1" />
      </geometry>
    </collision>
    <inertial>
      <mass value="0.03" />
      <origin rpy="0.000000 0.000000 0.000000" xyz="0.000000 0.000000 0.000000" />
      <inertia ixx="7e-06" ixy="0.0" ixz="0.0" iyy="7e-06" iyz="0.0" izz="1.35e-05" />
    </inertial>
  </link>
  <joint name="cobotta_joint_6" type="revolute">
    <parent link="cobotta_J5" />
    <child link="cobotta_J6" />
    <origin rpy="0.000000 0.000000 0.000000" xyz="0.000000 -0.044500 0.042000" />
    <axis xyz="-0.000000 -0.000000 1.000000" />
    <limit effort="10" lower="-2.96706" upper="2.96706" velocity="1.1093312725676" />
    <dynamics damping="0.001" friction="0.61" />
  </joint>
  <transmission name="cobotta_trans_6">
    <type>transmission_interface/SimpleTransmission</type>
    <joint name="cobotta_joint_6">
      <hardwareInterface>hardware_interface/PositionJointInterface</hardwareInterface>
    </joint>
    <actuator name="cobotta_motor_6">
      <hardwareInterface>hardware_interface/PositionJointInterface</hardwareInterface>
      <mechanicalReduction>1</mechanicalReduction>
    </actuator>
  </transmission>
  <link name="cobotta_gripper_base">
    <visual>
      <origin rpy="0 0 0" xyz="0.000000 0.000000 0.000000" />
      <geometry>
        <mesh filename="package://denso_cobotta_descriptions/cobotta_description/gripper_base.dae" scale="1 1 1" />
      </geometry>
    </visual>
    <collision>
      <origin rpy="0 0 0" xyz="0 0 0" />
      <geometry>
        <mesh filename="package://denso_cobotta_descriptions/cobotta_description/gripper_base.dae" scale="1 1 1" />
      </geometry>
    </collision>
    <inertial>
      <mass value="1" />
      <origin rpy="0.000000 0.000000 0.000000" xyz="0.000000 0.000000 0.000000" />
      <inertia ixx="1" ixy="0" ixz="0" iyy="1" iyz="0" izz="1" />
    </inertial>
  </link>
  <joint name="cobotta_joint_gripper_base" type="fixed">
    <parent link="cobotta_J6" />
    <child link="cobotta_gripper_base" />
    <origin rpy="0.000000 0.000000 0.000000" xyz="0.000000 0.000000 0.0000000" />
  </joint>

  <link name="cobotta_left_finger">
    <visual>
      <origin xyz="-0.008 0 -0.015" rpy="-1.5708 0 0"/>
      <geometry>
        <mesh
          filename="package://dual_robot_description/meshes/cobotta/COBOTTA_gripper_4.STL"
          scale="0.001 0.001 0.001"/>
      </geometry>
    </visual>
    <collision>
      <origin xyz="-0.008 0 -0.015" rpy="-1.5708 0 0"/>
      <geometry>
        <mesh
          filename="package://dual_robot_description/meshes/cobotta/COBOTTA_gripper_4.STL"
          scale="0.001 0.001 0.001"/>
      </geometry>
    </collision>
    <inertial>
      <mass value="1" />
      <origin rpy="0.000000 0.000000 0.000000" xyz="0.000000 0.000000 0.000000" />
      <inertia ixx="1" ixy="0" ixz="0" iyy="1" iyz="0" izz="1" />
    </inertial>
  </link>

  <joint name="cobotta_joint_gripper" type="prismatic">
    <parent link="cobotta_gripper_base" />
    <child link="cobotta_left_finger" />
    <origin rpy="0.000000 0.000000 0.000000" xyz="0.000000 0.000000 0.06000" />
    <axis xyz="-0.000000 1.000000 -0.000000" />
    <limit effort="20" lower="0.000000" upper="0.015000" velocity="0.040000" />
    <dynamics damping="0" friction="0" />
  </joint>
  <transmission name="cobotta_trans_gripper">
    <type>transmission_interface/SimpleTransmission</type>
    <joint name="cobotta_joint_gripper">
      <hardwareInterface>hardware_interface/PositionJointInterface</hardwareInterface>
    </joint>
    <actuator name="cobotta_motor_gripper">
      <hardwareInterface>hardware_interface/PositionJointInterface</hardwareInterface>
      <mechanicalReduction>1</mechanicalReduction>
    </actuator>
  </transmission>
  <link name="cobotta_right_finger">
    <visual>
      <origin xyz="0.002 0 -0.015"
              rpy="1.5708 3.14159 0"/>
      <geometry>
        <mesh
          filename="package://dual_robot_description/meshes/cobotta/COBOTTA_gripper_4.STL"
          scale="0.001 0.001 0.001"/>
      </geometry>
    </visual>
    <collision>
      <origin xyz="0.002 0 -0.015"
              rpy="1.5708 3.14159 0"/>
      <geometry>
        <mesh
          filename="package://dual_robot_description/meshes/cobotta/COBOTTA_gripper_4.STL"
          scale="0.001 0.001 0.001"/>
      </geometry>
    </collision>
    <inertial>
      <mass value="1" />
      <origin rpy="0.000000 0.000000 0.000000" xyz="0.000000 0.000000 0.000000" />
      <inertia ixx="1" ixy="0" ixz="0" iyy="1" iyz="0" izz="1" />
    </inertial>
  </link>

  <joint name="cobotta_joint_gripper_mimic" type="prismatic">
    <parent link="cobotta_gripper_base" />
    <child link="cobotta_right_finger" />
    <mimic joint="cobotta_joint_gripper" multiplier="-1.000000" offset="0.000000" />
    <origin rpy="0.000000 0.000000 0.000000" xyz="0.000000 0.000000 0.060000" />
    <axis xyz="-0.000000 1.000000 -0.000000" />
    <limit effort="20" lower="-0.015000" upper="0.000000" velocity="0.040000" />
    <dynamics damping="0" friction="0" />
  </joint>
  <ns0:property name="width" value=".2" />
  <link name="mycobot_base">
    <visual>
      <geometry>
        <mesh filename="package://mycobot_280_description_ros1/meshes/base.dae" />
      </geometry>
      <origin xyz="0.0 0 0 " rpy=" 0 0 -1.5708" />
    </visual>
    <collision>
      <geometry>
        <mesh filename="package://mycobot_280_description_ros1/meshes/base.dae" />
      </geometry>
      <origin xyz="0.0 0 0 " rpy=" 0 0 -1.5708" />
    </collision>
  </link>
  <link name="mycobot_link1">
    <visual>
      <geometry>
        <mesh filename="package://mycobot_280_description_ros1/meshes/link1.dae" />
      </geometry>
      <origin xyz="0.0 0 -0.06096 " rpy=" 0 0 -1.5708" />
    </visual>
    <collision>
      <geometry>
        <mesh filename="package://mycobot_280_description_ros1/meshes/link1.dae" />
      </geometry>
      <origin xyz="0.0 0 -0.06096 " rpy=" 0 0 -1.5708" />
    </collision>
  </link>
  <link name="mycobot_link2">
    <visual>
      <geometry>
        <mesh filename="package://mycobot_280_description_ros1/meshes/link2.dae" />
      </geometry>
      <origin xyz="0.0 0 0.03256 " rpy=" 0 -1.5708 0" />
    </visual>
    <collision>
      <geometry>
        <mesh filename="package://mycobot_280_description_ros1/meshes/link2.dae" />
      </geometry>
      <origin xyz="0.0 0 0.03256 " rpy=" 0 -1.5708 0" />
    </collision>
  </link>
  <link name="mycobot_link3">
    <visual>
      <geometry>
        <mesh filename="package://mycobot_280_description_ros1/meshes/link3.dae" />
      </geometry>
      <origin xyz="0.0 0 0.03056 " rpy=" 0 -1.5708 0" />
    </visual>
    <collision>
      <geometry>
        <mesh filename="package://mycobot_280_description_ros1/meshes/link3.dae" />
      </geometry>
      <origin xyz="0.0 0 0.03056 " rpy=" 0 -1.5708 0" />
    </collision>
  </link>
  <link name="mycobot_link4">
    <visual>
      <geometry>
        <mesh filename="package://mycobot_280_description_ros1/meshes/link4.dae" />
      </geometry>
      <origin xyz="0.0 0 -0.03356 " rpy=" -1.5708 0 0" />
    </visual>
    <collision>
      <geometry>
        <mesh filename="package://mycobot_280_description_ros1/meshes/link4.dae" />
      </geometry>
      <origin xyz="0.0 0 -0.03356 " rpy=" -1.5708 0 0" />
    </collision>
  </link>
  <link name="mycobot_link5">
    <visual>
      <geometry>
        <mesh filename="package://mycobot_280_description_ros1/meshes/link5.dae" />
      </geometry>
      <origin xyz="0 0.00 -0.038 " rpy=" 0 0 0" />
    </visual>
    <collision>
      <geometry>
        <mesh filename="package://mycobot_280_description_ros1/meshes/link5.dae" />
      </geometry>
      <origin xyz="0 0.00 -0.038 " rpy=" 0 0 0" />
    </collision>
  </link>

   <link name="mycobot_link6">
    <visual>
      <geometry>
        <mesh filename="package://mycobot_280_description_ros1/meshes/link6.dae" />
      </geometry>
      <origin xyz="0.0 0 -0.012" rpy="0 0 0" />
    </visual>
    <collision>
      <geometry>
        <mesh filename="package://mycobot_280_description_ros1/meshes/link6.dae" />
      </geometry>
      <origin xyz="0.0 0 -0.012" rpy="0 0 0" />
    </collision>
  </link>
 
  <!-- MyCobot吸着工具：方向確認用の仮モデル -->
  <link name="mycobot_tool_link">
    <visual>
      <origin xyz="0 0 0.010" rpy="0 0 0" />
      <geometry>
        <cylinder radius="0.014" length="0.020" />
      </geometry>
      <material name="mycobot_tool_black">
        <color rgba="0.15 0.15 0.15 1.0" />
      </material>
    </visual>

    <collision>
      <origin xyz="0 0 0.010" rpy="0 0 0" />
      <geometry>
        <cylinder radius="0.014" length="0.020" />
      </geometry>
    </collision>
  </link>

  <joint name="mycobot_tool_fixed_joint" type="fixed">
    <parent link="mycobot_link6" />
    <child link="mycobot_tool_link" />
    <origin xyz="0 0 0" rpy="0 0 0" />
  </joint>

  <joint name="mycobot_joint1" type="revolute">
    <axis xyz="0 0 1" />
    <limit effort="1000.0" lower="-3.14" upper="3.14159" velocity="0" />
    <parent link="mycobot_base" />
    <child link="mycobot_link1" />
    <origin xyz="0 0 0.13156" rpy="0 0 0" />
  </joint>
  <joint name="mycobot_joint2" type="revolute">
    <axis xyz="0 0 1" />
    <limit effort="1000.0" lower="-3.14" upper="3.14159" velocity="0" />
    <parent link="mycobot_link1" />
    <child link="mycobot_link2" />
    <origin xyz="0 0  0" rpy="0 1.5708 -1.5708" />
  </joint>
  <joint name="mycobot_joint3" type="revolute">
    <axis xyz=" 0 0 1" />
    <limit effort="1000.0" lower="-3.14" upper="3.14159" velocity="0" />
    <parent link="mycobot_link2" />
    <child link="mycobot_link3" />
    <origin xyz="  -0.1104 0 0   " rpy="0 0 0" />
  </joint>
  <joint name="mycobot_joint4" type="revolute">
    <axis xyz=" 0 0 1" />
    <limit effort="1000.0" lower="-3.14" upper="3.14159" velocity="0" />
    <parent link="mycobot_link3" />
    <child link="mycobot_link4" />
    <origin xyz="-0.096 0 0.06462" rpy="0 0 -1.5708" />
  </joint>
  <joint name="mycobot_joint5" type="revolute">
    <axis xyz="0 0 1" />
    <limit effort="1000.0" lower="-3.14" upper="3.14159" velocity="0" />
    <parent link="mycobot_link4" />
    <child link="mycobot_link5" />
    <origin xyz="0 -0.07318 0" rpy="1.5708 -1.5708 0" />
  </joint>
  <joint name="mycobot_joint6" type="revolute">
    <axis xyz="0 0 1" />
    <limit effort="1000.0" lower="-3.14" upper="3.14159" velocity="0" />
    <parent link="mycobot_link5" />
    <child link="mycobot_link6" />
    <origin xyz="0 0.0456 0" rpy="-1.5708 0 0" />
  </joint>
  <joint name="world_to_mycobot_base" type="fixed">
    <parent link="world" />
    <child link="mycobot_base" />
    <origin xyz="0.446 -0.070  0.080" rpy="0 0 3.14159" />
  </joint>
</robot>
